<?xml version="1.0" ?>
<mujoco model="Prototype v28">
	<compiler angle="radian" coordinate="local" inertiafromgeom="true" settotalmass="1"/>
	<default>
		<geom rgba="0.2 0.8 0.2 0.5"/>
		<site rgba=".9 .9 .9 1" size="0.1" type="sphere"/>
		<joint armature="0" damping="0"/>
		<motor gear="1"/>
	</default>
	<size nstack="300000" nuser_geom="1"/>
	<option gravity="0 0 -98.1" timestep="0.01"/>
	<asset>
		<texture builtin="gradient" height="100" rgb1=".4 .5 .6" rgb2="0 0 0" type="skybox" width="100"/>
		<texture builtin="flat" height="1278" mark="cross" markrgb="1 1 1" name="texgeom" random="0.01" rgb1="0.8 0.6 0.4" rgb2="0.8 0.6 0.4" type="cube" width="127"/>
		<texture builtin="checker" height="100" name="texplane" rgb1="0 0 0" rgb2="0.8 0.8 0.8" type="2d" width="100"/>
		<material name="groundplanemat" reflectance="0.5" shininess="1" specular="1" texrepeat="100 100" texture="texplane"/>
		<material name="geom" texture="texgeom" texuniform="true"/>
		<mesh file="odie_stl/Torso.stl" name="Torso" scale="1 1 1"/>
		<mesh file="odie_stl/FLLeg.stl" name="FLLeg" scale="1 1 1"/>
		<mesh file="odie_stl/FRLeg.stl" name="FRLeg" scale="1 1 1"/>
		<mesh file="odie_stl/BLLeg.stl" name="BLLeg" scale="1 1 1"/>
		<mesh file="odie_stl/BRLeg.stl" name="BRLeg" scale="1 1 1"/>
	</asset>
	<worldbody>
		<light cutoff="100" diffuse="1 1 1" dir="-0 0 -1.3" directional="true" exponent="1" pos="0 0 1.3" specular=".1 .1 .1"/>
		<geom conaffinity="1" condim="3" material="groundplanemat" name="floor" pos="0 0 0" rgba="0.8 0.9 0.8 1" size="1000 1000 1000" type="plane"/>
		<body name="Torso" pos="0.0 0.0 0.0">
			<geom mesh="Torso" type="mesh" rgba="0 0 1 1"/>
			<joint armature="0" axis="1 0 0" damping="0" limited="false" name="slide_x" pos="0 0 0" stiffness="0" type="slide"/>
			<joint armature="0" axis="0 1 0" damping="0" limited="false" name="slide_y" pos="0 0 0" stiffness="0" type="slide"/>
			<joint armature="0" axis="0 0 1" damping="0" limited="false" name="slide_z" pos="0 0 0" stiffness="0" type="slide"/>
			<joint armature="0" axis="1 0 0" damping="0" limited="false" name="hinge_x" pos="0 0 0" stiffness="0" type="hinge"/>
			<joint armature="0" axis="0 1 0" damping="0" limited="false" name="hinge_y" pos="0 0 0" stiffness="0" type="hinge"/>
			<joint armature="0" axis="0 0 1" damping="0" limited="false" name="hinge_z" pos="0 0 0" stiffness="0" type="hinge"/>
			<body name="FRLeg" pos="50.0 -25.0 -0.0">
				<geom mesh="FRLeg" type="mesh" rgba="1.0 0 0 1"/>
				<joint axis="0.0 1.0 0.0" name="Rev9" pos="0.0 0.0 65.0" type="hinge" limited="true" range="-0.785 0.785"/>
			</body>
			<body name="BRLeg" pos="-50.0 -25.0 0.0">
				<geom mesh="BRLeg" type="mesh" rgba="0.8 0.6 0 1"/>
				<joint axis="0.0 1.0 0.0" name="Rev10" pos="0.0 0.0 65.0" type="hinge" limited="true" range="-0.785 0.785"/>
			</body>
			<body name="FLLeg" pos="50.0 25.0 -0.0">
				<geom mesh="FLLeg" type="mesh" rgba="0 0.9 0 1"/>
				<joint axis="0.0 -1.0 -0.0" name="Rev11" pos="0.0 0.0 65.0" type="hinge" limited="true" range="-0.785 0.785"/>
			</body>
			<body name="BLLeg" pos="-50.0 25.0 0.0">
				<geom mesh="BLLeg" type="mesh" rgba="0 0.6 0.8 1"/>
				<joint axis="0.0 -1.0 -0.0" name="Rev12" pos="0.0 0.0 65.0" type="hinge" limited="true" range="-0.785 0.785"/>
			</body>
		</body>
	</worldbody>
	<tendon/>
	<actuator>
		<motor gear="5000" joint="Rev9" name="FRLeg"/>
		<motor gear="5000" joint="Rev10" name="BRLeg"/>
		<motor gear="5000" joint="Rev11" name="FLLeg"/>
		<motor gear="5000" joint="Rev12" name="BLLeg"/>
	</actuator>
</mujoco>
